Workbook

Sheet Lead Tracker
B1: Brochure as a Service — Lead Tracker
B2: Track every prospect from discovery to close. Update daily.
A4: INTEREST | B4: Business Name | C4: Industry | D4: Province | E4: City / Suburb | F4: Contact Person | G4: Phone / WhatsApp | H4: Email | I4: Facebook / Insta | J4: Has Website? | K4: Lead Source | L4: Status | M4: Date Found | N4: Date Contacted | O4: Notes / Next Step
A5: Tiling Experts | B5: Trades & Home Services | C5: KwaZulu-Natal | D5: La Lucia | F5: 082 753 0350 | I5: No | J5: Google Maps | K5: New Lead | L5: 2026-04-03 | N5: 4.8 stars | 23 reviews | Monday: 7:30 AM – 4:00 PM | Tuesday: 7:30 AM – 4:00 PM | Wednesday: 7:30 AM – 4:00 PM | https://maps.google.com/?cid=8098614939933451806&g_mp=Cidnb29nbGUubWFwcy5wbGFjZXMudjEuUGxhY2VzLlNlYXJjaFRleHQQAhgEIAA | O5: 4.6 stars | P5: 21 reviews | Q5: Monday: Open 24 hours | R5: Tuesday: Open 24 hours | S5: Wednesday: Open 24 hours | T5: https://maps.google.com/?cid=11818391474367614897&g_mp=Cidnb29nbGUubWFwcy5wbGFjZXMudjEuUGxhY2VzLlNlYXJjaFRleHQQAhgEIAA
A6: Beauty Kingdom | B6: Beauty & Wellness | C6: KwaZulu-Natal | D6: Chatsworth | F6: 031 401 8659 | I6: No | J6: Google Maps | K6: New Lead | L6: 2026-04-03 | N6: 4.6 stars | 341 reviews | Monday: 9:00 AM – 6:00 PM | Tuesday: 9:00 AM – 6:00 PM | Wednesday: 9:00 AM – 6:00 PM | https://maps.google.com/?cid=5902211889831189732&g_mp=Cidnb29nbGUubWFwcy5wbGFjZXMudjEuUGxhY2VzLlNlYXJjaFRleHQQAhgEIAA | O6: 1 stars | P6: 1 reviews | Q6: Monday: Open 24 hours | R6: Tuesday: Open 24 hours | S6: Wednesday: Open 24 hours | T6: https://maps.google.com/?cid=5993838295370130051&g_mp=Cidnb29nbGUubWFwcy5wbGFjZXMudjEuUGxhY2VzLlNlYXJjaFRleHQQAhgEIAA
A7: HALEY’S BEAUTY THERAPY | B7: Beauty & Wellness | C7: KwaZulu-Natal | D7: Chatsworth | F7: 081 267 4248 | I7: No | J7: Google Maps | K7: New Lead | L7: 2026-04-03 | N7: 4.8 stars | 146 reviews | Monday: 12:00 – 6:00 PM | Tuesday: 10:00 AM – 6:00 PM | Wednesday: 10:00 AM – 6:00 PM | https://maps.google.com/?cid=7212798743767500606&g_mp=Cidnb29nbGUubWFwcy5wbGFjZXMudjEuUGxhY2VzLlNlYXJjaFRleHQQAhgEIAA | O7: 5 stars | P7: 24 reviews | Q7: Monday: Open 24 hours | R7: Tuesday: Open 24 hours | S7: Wednesday: Open 24 hours | T7: https://maps.google.com/?cid=6965501395366097317&g_mp=Cidnb29nbGUubWFwcy5wbGFjZXMudjEuUGxhY2VzLlNlYXJjaFRleHQQAhgEIAA
A8: The Beauty Vault Sanctuary Spa | B8: Beauty & Wellness | C8: KwaZulu-Natal | D8: Chatsworth | F8: 084 923 5216 | I8: No | J8: Google Maps | K8: New Lead | L8: 2026-04-03 | N8: Monday: 7:00 AM – 8:00 PM | Tuesday: 7:00 AM – 8:00 PM | Wednesday: 7:00 AM – 8:00 PM | https://maps.google.com/?cid=5897106547258168965&g_mp=Cidnb29nbGUubWFwcy5wbGFjZXMudjEuUGxhY2VzLlNlYXJjaFRleHQQAhgEIAA | O8: 3.8 stars | P8: 4 reviews | Q8: Monday: 6:00 AM – 10:00 PM | R8: Tuesday: 6:00 AM – 10:00 PM | S8: Wednesday: 6:00 AM – 10:00 PM | T8: https://maps.google.com/?cid=2572711291238925426&g_mp=Cidnb29nbGUubWFwcy5wbGFjZXMudjEuUGxhY2VzLlNlYXJjaFRleHQQAhgEIAA
A9: THE GLAM STUDIO | B9: Beauty & Wellness | C9: KwaZulu-Natal | D9: Chatsworth | F9: 079 882 6161 | I9: No | J9: Google Maps | K9: New Lead | L9: 2026-04-03 | N9: 4.6 stars | 23 reviews | Monday: Closed | Tuesday: 8:30 AM – 5:00 PM | Wednesday: 8:30 AM – 5:00 PM | https://maps.google.com/?cid=5935282822695831857&g_mp=Cidnb29nbGUubWFwcy5wbGFjZXMudjEuUGxhY2VzLlNlYXJjaFRleHQQAhgEIAA | O9: 5 stars | P9: 1 reviews | Q9: Monday: Open 24 hours | R9: Tuesday: Open 24 hours | S9: Wednesday: Open 24 hours | T9: https://maps.google.com/?cid=11466610932631644100&g_mp=Cidnb29nbGUubWFwcy5wbGFjZXMudjEuUGxhY2VzLlNlYXJjaFRleHQQAhgEIAA
A10: Pearl's Beauty Lab | B10: Beauty & Wellness | C10: KwaZulu-Natal | D10: Chatsworth | F10: 073 606 9534 | I10: No | J10: Google Maps | K10: New Lead | L10: 2026-04-03 | N10: 5 stars | 16 reviews | Monday: 9:00 AM – 5:00 PM | Tuesday: 9:00 AM – 5:00 PM | Wednesday: 9:00 AM – 5:00 PM | https://maps.google.com/?cid=10237563139231933977&g_mp=Cidnb29nbGUubWFwcy5wbGFjZXMudjEuUGxhY2VzLlNlYXJjaFRleHQQAhgEIAA | O10: 5 stars | P10: 1 reviews | Q10: Monday: 7:30 AM – 5:00 PM | R10: Tuesday: 7:30 AM – 5:00 PM | S10: Wednesday: 7:30 AM – 5:00 PM | T10: https://maps.google.com/?cid=9597037575641056009&g_mp=Cidnb29nbGUubWFwcy5wbGFjZXMudjEuUGxhY2VzLlNlYXJjaFRleHQQAhgEIAA
A11: Rejuvenation Retreat | B11: Beauty & Wellness | C11: KwaZulu-Natal | D11: Chatsworth | F11: 071 365 0275 | I11: No | J11: Google Maps | K11: New Lead | L11: 2026-04-03 | N11: 5 stars | 1 reviews | Monday: 9:00 AM – 6:00 PM | Tuesday: 9:00 AM – 6:00 PM | Wednesday: 9:00 AM – 6:00 PM | https://maps.google.com/?cid=4407304906041593885&g_mp=Cidnb29nbGUubWFwcy5wbGFjZXMudjEuUGxhY2VzLlNlYXJjaFRleHQQAhgEIAA | O11: 5 stars | P11: 2 reviews | Q11: Monday: Open 24 hours | R11: Tuesday: Open 24 hours | S11: Wednesday: Open 24 hours | T11: https://maps.google.com/?cid=2355159315617690695&g_mp=Cidnb29nbGUubWFwcy5wbGFjZXMudjEuUGxhY2VzLlNlYXJjaFRleHQQAhgEIAA
A12: The Nail Hive & Beauty | B12: Beauty & Wellness | C12: KwaZulu-Natal | D12: Chatsworth | F12: 081 215 1786 | I12: No | J12: Google Maps | K12: New Lead | L12: 2026-04-03 | N12: 5 stars | 16 reviews | Monday: 9:00 AM – 5:00 PM | Tuesday: 9:00 AM – 5:00 PM | Wednesday: 9:00 AM – 5:00 PM | https://maps.google.com/?cid=12886772067834600651&g_mp=Cidnb29nbGUubWFwcy5wbGFjZXMudjEuUGxhY2VzLlNlYXJjaFRleHQQAhgEIAA | O12: 4.9 stars | P12: 62 reviews | Q12: Monday: Open 24 hours | R12: Tuesday: Open 24 hours | S12: Wednesday: Open 24 hours | T12: https://maps.google.com/?cid=16454109922237301018&g_mp=Cidnb29nbGUubWFwcy5wbGFjZXMudjEuUGxhY2VzLlNlYXJjaFRleHQQAhgEIAA
A13: Thee Beauty Hideout | B13: Beauty & Wellness | C13: KwaZulu-Natal | D13: Chatsworth | F13: 081 259 5141 | I13: No | J13: Google Maps | K13: New Lead | L13: 2026-04-03 | N13: 4 stars | 3 reviews | Monday: 9:00 AM – 5:30 PM | Tuesday: 9:00 AM – 5:30 PM | Wednesday: 9:00 AM – 5:30 PM | https://maps.google.com/?cid=12514477215559661852&g_mp=Cidnb29nbGUubWFwcy5wbGFjZXMudjEuUGxhY2VzLlNlYXJjaFRleHQQAhgEIAA | O13: 4.9 stars | P13: 28 reviews | Q13: Monday: Open 24 hours | R13: Tuesday: Open 24 hours | S13: Wednesday: Open 24 hours | T13: https://maps.google.com/?cid=16078506622121649025&g_mp=Cidnb29nbGUubWFwcy5wbGFjZXMudjEuUGxhY2VzLlNlYXJjaFRleHQQAhgEIAA
A14: La Tierra Spa & Aesthetics | B14: Beauty & Wellness | C14: KwaZulu-Natal | D14: Chatsworth | F14: 084 722 6900 | I14: No | J14: Google Maps | K14: New Lead | L14: 2026-04-03 | N14: 4.8 stars | 65 reviews | Monday: Closed | Tuesday: 8:00 AM – 5:00 PM | Wednesday: 8:00 AM – 5:00 PM | https://maps.google.com/?cid=3785612442891382587&g_mp=Cidnb29nbGUubWFwcy5wbGFjZXMudjEuUGxhY2VzLlNlYXJjaFRleHQQAhgEIAA | O14: 5 stars | P14: 3 reviews | Q14: Monday: 8:00 AM – 4:00 PM | R14: Tuesday: 8:00 AM – 4:00 PM | S14: Wednesday: 8:00 AM – 4:00 PM | T14: https://maps.google.com/?cid=675367582599982263&g_mp=Cidnb29nbGUubWFwcy5wbGFjZXMudjEuUGxhY2VzLlNlYXJjaFRleHQQAhgEIAA
A15: CHARLOTTES HEALTH AND BEAUTY | B15: Beauty & Wellness | C15: KwaZulu-Natal | D15: Chatsworth | F15: 031 401 9350 | I15: No | J15: Google Maps | K15: New Lead | L15: 2026-04-03 | N15: 4.9 stars | 26 reviews | Monday: 8:00 AM – 5:00 PM | Tuesday: 8:00 AM – 5:00 PM | Wednesday: 8:00 AM – 5:00 PM | https://maps.google.com/?cid=14208271565492437224&g_mp=Cidnb29nbGUubWFwcy5wbGFjZXMudjEuUGxhY2VzLlNlYXJjaFRleHQQAhgEIAA | O15: 4.8 stars | P15: 4 reviews | Q15: Monday: Open 24 hours | R15: Tuesday: Open 24 hours | S15: Wednesday: Open 24 hours | T15: https://maps.google.com/?cid=13689332527613132762&g_mp=Cidnb29nbGUubWFwcy5wbGFjZXMudjEuUGxhY2VzLlNlYXJjaFRleHQQAhgEIAA
A16: AD Hair Nails & Beauty Spa | B16: Beauty & Wellness | C16: KwaZulu-Natal | D16: Chatsworth | F16: 031 002 7403 | I16: No | J16: Google Maps | K16: New Lead | L16: 2026-04-03 | N16: 5 stars | 9 reviews | Monday: 9:00 AM – 5:00 PM | Tuesday: 9:00 AM – 5:00 PM | Wednesday: 9:00 AM – 5:00 PM | https://maps.google.com/?cid=4077210597883238985&g_mp=Cidnb29nbGUubWFwcy5wbGFjZXMudjEuUGxhY2VzLlNlYXJjaFRleHQQAhgEIAA | O16: 3.4 stars | P16: 20 reviews | Q16: Monday: Open 24 hours | R16: Tuesday: Open 24 hours | S16: Wednesday: Open 24 hours | T16: https://maps.google.com/?cid=176932451788830868&g_mp=Cidnb29nbGUubWFwcy5wbGFjZXMudjEuUGxhY2VzLlNlYXJjaFRleHQQAhgEIAA
... A18: Crystal Spa and Aesthetics | B18: Beauty & Wellness | C18: KwaZulu-Natal | D18: Chatsworth | F18: 069 993 1620 | I18: No | J18: Google Maps | K18: New Lead | L18: 2026-04-03 | N18: 4 stars | 4 reviews | Monday: 8:00 AM – 7:00 PM | Tuesday: 8:00 AM – 7:00 PM | Wednesday: 8:00 AM – 7:00 PM | https://maps.google.com/?cid=2183555200601980177&g_mp=Cidnb29nbGUubWFwcy5wbGFjZXMudjEuUGxhY2VzLlNlYXJjaFRleHQQAhgEIAA | O18: 4.7 stars | P18: 20 reviews | Q18: Monday: Open 24 hours | R18: Tuesday: Open 24 hours | S18: Wednesday: Open 24 hours | T18: https://maps.google.com/?cid=11962099371799953956&g_mp=Cidnb29nbGUubWFwcy5wbGFjZXMudjEuUGxhY2VzLlNlYXJjaFRleHQQAhgEIAA
A19: Le' beautè Salon | B19: Beauty & Wellness | C19: KwaZulu-Natal | D19: Chatsworth | F19: 082 321 5631 | I19: No | J19: Google Maps | K19: New Lead | L19: 2026-04-03 | N19: Monday: 9:00 AM – 5:00 PM | Tuesday: 9:00 AM – 5:00 PM | Wednesday: 9:00 AM – 5:00 PM | https://maps.google.com/?cid=1658288402048617539&g_mp=Cidnb29nbGUubWFwcy5wbGFjZXMudjEuUGxhY2VzLlNlYXJjaFRleHQQAhgEIAA | O19: 4.9 stars | P19: 12 reviews | Q19: https://maps.google.com/?cid=16758636031194280299&g_mp=Cidnb29nbGUubWFwcy5wbGFjZXMudjEuUGxhY2VzLlNlYXJjaFRleHQQAhgEIAA
A20: Graham's Appliances & Refrigeration | B20: Trades & Home Services | C20: Western Cape | D20: Strand | F20: 021 853 1163 | I20: No | J20: Google Maps | K20: New Lead | L20: 2026-04-03 | N20: 3.7 stars | 256 reviews | Monday: 8:00 AM – 5:00 PM | Tuesday: 8:00 AM – 5:00 PM | Wednesday: 8:00 AM – 5:00 PM | https://maps.google.com/?cid=10690443470884824657&g_mp=Cidnb29nbGUubWFwcy5wbGFjZXMudjEuUGxhY2VzLlNlYXJjaFRleHQQAhgEIAA | O20: 5 stars | P20: 3 reviews | Q20: Monday: 8:00 AM – 5:00 PM | R20: Tuesday: 8:00 AM – 5:00 PM | S20: Wednesday: 8:00 AM – 5:00 PM | T20: https://maps.google.com/?cid=14973091405830133352&g_mp=Cidnb29nbGUubWFwcy5wbGFjZXMudjEuUGxhY2VzLlNlYXJjaFRleHQQAhgEIAA
A21: ARS Air-Conditioning & Refrigeration services | B21: Trades & Home Services | C21: Western Cape | D21: Strand | F21: 082 367 6000 | I21: No | J21: Google Maps | K21: New Lead | L21: 2026-04-03 | N21: 5 stars | 2 reviews | Monday: 8:00 AM – 5:00 PM | Tuesday: 8:00 AM – 5:00 PM | Wednesday: 8:00 AM – 5:00 PM | https://maps.google.com/?cid=16057294301577441192&g_mp=Cidnb29nbGUubWFwcy5wbGFjZXMudjEuUGxhY2VzLlNlYXJjaFRleHQQAhgEIAA | O21: 4.9 stars | P21: 38 reviews | Q21: Monday: 8:00 AM – 6:00 PM | R21: Tuesday: 8:00 AM – 6:00 PM | S21: Wednesday: 8:00 AM – 6:00 PM | T21: https://maps.google.com/?cid=1126306609276102971&g_mp=Cidnb29nbGUubWFwcy5wbGFjZXMudjEuUGxhY2VzLlNlYXJjaFRleHQQAhgEIAA
A22: MOBILE CAR AIRCON REGAS & BATTERIES | B22: Trades & Home Services | C22: Western Cape | D22: Strand | F22: 064 408 4632 | I22: No | J22: Google Maps | K22: New Lead | L22: 2026-04-03 | N22: 5 stars | 12 reviews | Monday: 8:00 AM – 8:00 PM | Tuesday: 8:00 AM – 8:00 PM | Wednesday: 8:00 AM – 8:00 PM | https://maps.google.com/?cid=18243218095361922341&g_mp=Cidnb29nbGUubWFwcy5wbGFjZXMudjEuUGxhY2VzLlNlYXJjaFRleHQQAhgEIAA | O22: 5 stars | P22: 1 reviews | Q22: Monday: Open 24 hours | R22: Tuesday: Open 24 hours | S22: Wednesday: Open 24 hours | T22: https://maps.google.com/?cid=6697354469424328163&g_mp=Cidnb29nbGUubWFwcy5wbGFjZXMudjEuUGxhY2VzLlNlYXJjaFRleHQQAhgEIAA
A23: Nick & Ethan Pest Control | B23: Trades & Home Services | C23: Western Cape | D23: Fish Hoek | F23: 074 356 6279 | I23: No | J23: Google Maps | K23: New Lead | L23: 2026-04-03 | N23: 4.9 stars | 56 reviews | Monday: Open 24 hours | Tuesday: Open 24 hours | Wednesday: Open 24 hours | https://maps.google.com/?cid=7832124028168743916&g_mp=Cidnb29nbGUubWFwcy5wbGFjZXMudjEuUGxhY2VzLlNlYXJjaFRleHQQAhgEIAA | O23: 5 stars | P23: 1 reviews | Q23: Monday: 8:00 AM – 5:00 PM | R23: Tuesday: 8:00 AM – 5:00 PM | S23: Wednesday: 8:00 AM – 5:00 PM | T23: https://maps.google.com/?cid=12202758347105124936&g_mp=Cidnb29nbGUubWFwcy5wbGFjZXMudjEuUGxhY2VzLlNlYXJjaFRleHQQAhgEIAA
A24: King's Kid Creche | B24: Professional Services | C24: Western Cape | D24: Gardens | F24: 012 753 3527 | I24: No | J24: Google Maps | K24: New Lead | L24: 2026-04-03 | N24: 4.8 stars | 9 reviews | Monday: 6:30 AM – 5:30 PM | Tuesday: 6:30 AM – 5:30 PM | Wednesday: 6:30 AM – 5:30 PM | https://maps.google.com/?cid=7241707342309437473&g_mp=Cidnb29nbGUubWFwcy5wbGFjZXMudjEuUGxhY2VzLlNlYXJjaFRleHQQAhgEIAA | O24: 5 stars | P24: 1 reviews | Q24: Monday: 7:30 AM – 5:00 PM | R24: Tuesday: 7:00 AM – 5:00 PM | S24: Wednesday: 7:00 AM – 5:00 PM | T24: https://maps.google.com/?cid=9731750060488759204&g_mp=Cidnb29nbGUubWFwcy5wbGFjZXMudjEuUGxhY2VzLlNlYXJjaFRleHQQAhgEIAA
A25: Handyman Services and building renovators | B25: Trades & Home Services | C25: Gauteng | D25: Fourways | F25: 083 645 4329 | I25: No | J25: Google Maps | K25: New Lead | L25: 2026-04-03 | N25: 5 stars | 3 reviews | Monday: 7:00 AM – 10:00 PM | Tuesday: 7:00 AM – 10:00 PM | Wednesday: 7:00 AM – 10:00 PM | https://maps.google.com/?cid=10579546401697342776&g_mp=Cidnb29nbGUubWFwcy5wbGFjZXMudjEuUGxhY2VzLlNlYXJjaFRleHQQAhgEIAA | O25: Monday: 9:00 AM – 5:00 PM | P25: Tuesday: 9:00 AM – 5:00 PM | Q25: Wednesday: 9:00 AM – 5:00 PM | R25: https://maps.google.com/?cid=18348841273857454593&g_mp=Cidnb29nbGUubWFwcy5wbGFjZXMudjEuUGxhY2VzLlNlYXJjaFRleHQQAhgEIAA
A26: PureSkill Handyman Services | B26: Trades & Home Services | C26: Gauteng | D26: Fourways | F26: 084 435 9864 | I26: No | J26: Google Maps | K26: New Lead | L26: 2026-04-03 | N26: 4.5 stars | 2 reviews | Monday: Open 24 hours | Tuesday: Open 24 hours | Wednesday: Open 24 hours | https://maps.google.com/?cid=16363898909164060442&g_mp=Cidnb29nbGUubWFwcy5wbGFjZXMudjEuUGxhY2VzLlNlYXJjaFRleHQQAhgEIAA | O26: 5 stars | P26: 187 reviews | Q26: Monday: 8:00 AM – 5:00 PM | R26: Tuesday: 8:00 AM – 5:00 PM | S26: Wednesday: 8:00 AM – 5:00 PM | T26: https://maps.google.com/?cid=17922152422532051932&g_mp=Cidnb29nbGUubWFwcy5wbGFjZXMudjEuUGxhY2VzLlNlYXJjaFRleHQQAhgEIAA
A27: Stark Property Maintenance Pty Ltd | B27: Trades & Home Services | C27: Gauteng | D27: Fourways | F27: 060 278 4717 | I27: No | J27: Google Maps | K27: New Lead | L27: 2026-04-03 | N27: 4.9 stars | 38 reviews | Monday: 8:00 AM – 6:00 PM | Tuesday: 8:00 AM – 6:00 PM | Wednesday: 8:00 AM – 6:00 PM | https://maps.google.com/?cid=1126306609276102971&g_mp=Cidnb29nbGUubWFwcy5wbGFjZXMudjEuUGxhY2VzLlNlYXJjaFRleHQQAhgEIAA | O27: Monday: 9:00 AM – 6:00 PM | P27: Tuesday: 9:00 AM – 6:00 PM | Q27: Wednesday: 9:00 AM – 6:00 PM | R27: https://maps.google.com/?cid=16154884876342292094&g_mp=Cidnb29nbGUubWFwcy5wbGFjZXMudjEuUGxhY2VzLlNlYXJjaFRleHQQAhgEIAA
A28: Lp handyman services | B28: Trades & Home Services | C28: Gauteng | D28: Fourways | F28: 064 506 8167 | I28: No | J28: Google Maps | K28: New Lead | L28: 2026-04-03 | N28: 5 stars | 1 reviews | Monday: Open 24 hours | Tuesday: Open 24 hours | Wednesday: Open 24 hours | https://maps.google.com/?cid=6697354469424328163&g_mp=Cidnb29nbGUubWFwcy5wbGFjZXMudjEuUGxhY2VzLlNlYXJjaFRleHQQAhgEIAA | O28: 4.9 stars | P28: 35 reviews | Q28: Monday: 8:00 AM – 5:00 PM | R28: Tuesday: 8:00 AM – 5:00 PM | S28: Wednesday: 8:00 AM – 5:00 PM | T28: https://maps.google.com/?cid=16490594898542080455&g_mp=Cidnb29nbGUubWFwcy5wbGFjZXMudjEuUGxhY2VzLlNlYXJjaFRleHQQAhgEIAA
A29: SPJ HANDYMANSERVICES | B29: Trades & Home Services | C29: Gauteng | D29: Fourways | F29: 067 864 0570 | I29: No | J29: Google Maps | K29: New Lead | L29: 2026-04-03 | N29: 5 stars | 1 reviews | Monday: Open 24 hours | Tuesday: Open 24 hours | Wednesday: Open 24 hours | https://maps.google.com/?cid=17489594083991308585&g_mp=Cidnb29nbGUubWFwcy5wbGFjZXMudjEuUGxhY2VzLlNlYXJjaFRleHQQAhgEIAA | O29: 5 stars | P29: 5 reviews | Q29: Monday: Open 24 hours | R29: Tuesday: Open 24 hours | S29: Wednesday: Open 24 hours | T29: https://maps.google.com/?cid=705454782546344867&g_mp=Cidnb29nbGUubWFwcy5wbGFjZXMudjEuUGxhY2VzLlNlYXJjaFRleHQQAhgEIAA
A30: Jayden Handyman | B30: Trades & Home Services | C30: Gauteng | D30: Fourways | F30: 068 662 2533 | I30: No | J30: Google Maps | K30: New Lead | L30: 2026-04-03 | N30: 4.9 stars | 12 reviews | https://maps.google.com/?cid=16758636031194280299&g_mp=Cidnb29nbGUubWFwcy5wbGFjZXMudjEuUGxhY2VzLlNlYXJjaFRleHQQAhgEIAA | O30: 4.9 stars | P30: 158 reviews | Q30: Monday: 8:00 AM – 5:00 PM | R30: Tuesday: 8:00 AM – 5:00 PM | S30: Wednesday: 8:00 AM – 5:00 PM | T30: https://maps.google.com/?cid=11152493120617911190&g_mp=Cidnb29nbGUubWFwcy5wbGFjZXMudjEuUGxhY2VzLlNlYXJjaFRleHQQAhgEIAA
A31: At Your Place Catering | B31: Food & Hospitality | C31: Gauteng | D31: Menlyn | F31: 084 503 8661 | I31: No | J31: Google Maps | K31: New Lead | L31: 2026-04-03 | N31: 5 stars | 1 reviews | Monday: 8:00 AM – 5:00 PM | Tuesday: 8:00 AM – 5:00 PM | Wednesday: 8:00 AM – 5:00 PM | https://maps.google.com/?cid=11214900659229279853&g_mp=Cidnb29nbGUubWFwcy5wbGFjZXMudjEuUGxhY2VzLlNlYXJjaFRleHQQAhgEIAA | O31: 3.4 stars | P31: 7 reviews | Q31: Monday: 8:30 AM – 6:30 PM | R31: Tuesday: 8:30 AM – 6:30 PM | S31: Wednesday: 7:30 AM – 6:30 PM | T31: https://maps.google.com/?cid=15971280205286167228&g_mp=Cidnb29nbGUubWFwcy5wbGFjZXMudjEuUGxhY2VzLlNlYXJjaFRleHQQAhgEIAA
A32: Soulfood catering | B32: Food & Hospitality | C32: Gauteng | D32: Menlyn | I32: No | J32: Google Maps | K32: New Lead | L32: 2026-04-03 | N32: https://maps.google.com/?cid=2127642918173484467&g_mp=Cidnb29nbGUubWFwcy5wbGFjZXMudjEuUGxhY2VzLlNlYXJjaFRleHQQAhgEIAA | O32: 4.8 stars | P32: 16 reviews | Q32: Monday: 8:00 AM – 6:00 PM | R32: Tuesday: 8:00 AM – 6:00 PM | S32: Wednesday: 8:00 AM – 6:00 PM | T32: https://maps.google.com/?cid=17139290106882878602&g_mp=Cidnb29nbGUubWFwcy5wbGFjZXMudjEuUGxhY2VzLlNlYXJjaFRleHQQAhgEIAA
A33: Sankofa Specialist Caterers | B33: Food & Hospitality | C33: Gauteng | D33: Menlyn | F33: 082 461 0321 | I33: No | J33: Google Maps | K33: New Lead | L33: 2026-04-03 | N33: 5 stars | 4 reviews | Monday: 7:00 AM – 4:00 PM | Tuesday: 7:00 AM – 4:00 PM | Wednesday: 7:00 AM – 4:00 PM | https://maps.google.com/?cid=580253518917349460&g_mp=Cidnb29nbGUubWFwcy5wbGFjZXMudjEuUGxhY2VzLlNlYXJjaFRleHQQAhgEIAA | O33: 4.1 stars | P33: 110 reviews | Q33: https://maps.google.com/?cid=14422666823983000248&g_mp=Cidnb29nbGUubWFwcy5wbGFjZXMudjEuUGxhY2VzLlNlYXJjaFRleHQQAhgEIAA
A34: MENLYN SELF CATERING | B34: Food & Hospitality | C34: Gauteng | D34: Menlyn | F34: 076 288 8600 | I34: No | J34: Google Maps | K34: New Lead | L34: 2026-04-03 | N34: Monday: 8:00 AM – 7:00 PM | Tuesday: 8:00 AM – 7:00 PM | Wednesday: 8:00 AM – 7:00 PM | https://maps.google.com/?cid=2465957039450054252&g_mp=Cidnb29nbGUubWFwcy5wbGFjZXMudjEuUGxhY2VzLlNlYXJjaFRleHQQAhgEIAA | O34: 4.3 stars | P34: 8 reviews | Q34: Monday: 8:00 AM – 5:00 PM | R34: Tuesday: 8:00 AM – 5:00 PM | S34: Wednesday: 8:00 AM – 5:00 PM | T34: https://maps.google.com/?cid=65151722494489817&g_mp=Cidnb29nbGUubWFwcy5wbGFjZXMudjEuUGxhY2VzLlNlYXJjaFRleHQQAhgEIAA
A35: The Second Wife | B35: Food & Hospitality | C35: KwaZulu-Natal | D35: Chatsworth | F35: 061 133 1234 | I35: No | J35: Google Maps | K35: New Lead | L35: 2026-04-04 | N35: 3.5 stars | 253 reviews | Monday: 10:00 AM – 9:00 PM | Tuesday: 10:00 AM – 9:00 PM | Wednesday: 10:00 AM – 9:00 PM | https://maps.google.com/?cid=2346574056258469311&g_mp=Cidnb29nbGUubWFwcy5wbGFjZXMudjEuUGxhY2VzLlNlYXJjaFRleHQQAhgEIAA | O35: 5 stars | P35: 5 reviews | Q35: Monday: 7:00 AM – 6:00 PM | R35: Tuesday: 7:00 AM – 6:00 PM | S35: Wednesday: 7:00 AM – 6:00 PM | T35: https://maps.google.com/?cid=16038360317746772705&g_mp=Cidnb29nbGUubWFwcy5wbGFjZXMudjEuUGxhY2VzLlNlYXJjaFRleHQQAhgEIAA
A36: Copper Chimney | B36: Food & Hospitality | C36: KwaZulu-Natal | D36: Chatsworth | F36: 031 401 3812 | I36: No | J36: Google Maps | K36: New Lead | L36: 2026-04-04 | N36: 3.4 stars | 217 reviews | Monday: Open 24 hours | Tuesday: Open 24 hours | Wednesday: Open 24 hours | https://maps.google.com/?cid=2798449959599497030&g_mp=Cidnb29nbGUubWFwcy5wbGFjZXMudjEuUGxhY2VzLlNlYXJjaFRleHQQAhgEIAA | O36: 4.3 stars | P36: 24 reviews | Q36: Monday: 8:00 – 11:00 AM, 3:00 – 5:30 PM | R36: Tuesday: 8:00 – 11:00 AM, 3:00 – 5:30 PM | S36: Wednesday: 8:00 – 11:00 AM, 3:00 – 5:30 PM | T36: https://maps.google.com/?cid=14681080575329359722&g_mp=Cidnb29nbGUubWFwcy5wbGFjZXMudjEuUGxhY2VzLlNlYXJjaFRleHQQAhgEIAA
A37: Govinda's Restaurant & Boutique | B37: Food & Hospitality | C37: KwaZulu-Natal | D37: Chatsworth | F37: 031 403 3328 | I37: No | J37: Google Maps | K37: New Lead | L37: 2026-04-04 | N37: 4.7 stars | 55 reviews | Monday: 9:30 AM – 6:00 PM | Tuesday: 9:30 AM – 6:00 PM | Wednesday: 9:30 AM – 6:00 PM | https://maps.google.com/?cid=14320850139577209005&g_mp=Cidnb29nbGUubWFwcy5wbGFjZXMudjEuUGxhY2VzLlNlYXJjaFRleHQQAhgEIAA | O37: 4.4 stars | P37: 107 reviews | Q37: Monday: 9:00 AM – 12:30 PM, 3:30 – 6:00 PM | R37: Tuesday: 9:00 AM – 12:30 PM, 3:30 – 6:00 PM | S37: Wednesday: 9:00 AM – 12:30 PM, 3:30 – 6:00 PM | T37: https://maps.google.com/?cid=14435866198734539550&g_mp=Cidnb29nbGUubWFwcy5wbGFjZXMudjEuUGxhY2VzLlNlYXJjaFRleHQQAhgEIAA
A38: Checotah Spur Steak Ranch (Halaal) | B38: Food & Hospitality | C38: KwaZulu-Natal | D38: Chatsworth | I38: No | J38: Google Maps | K38: New Lead | L38: 2026-04-04 | N38: 4.1 stars | 1049 reviews | Monday: 8:00 AM – 9:00 PM | Tuesday: 8:00 AM – 9:00 PM | Wednesday: 8:00 AM – 9:00 PM | https://maps.google.com/?cid=5953807309119302951&g_mp=Cidnb29nbGUubWFwcy5wbGFjZXMudjEuUGxhY2VzLlNlYXJjaFRleHQQAhgEIAA | O38: 5 stars | P38: 3 reviews | Q38: Monday: 8:00 AM – 6:00 PM | R38: Tuesday: 8:00 AM – 6:00 PM | S38: Wednesday: 8:00 AM – 6:00 PM | T38: https://maps.google.com/?cid=5879414624676292877&g_mp=Cidnb29nbGUubWFwcy5wbGFjZXMudjEuUGxhY2VzLlNlYXJjaFRleHQQAhgEIAA
A39: Cronos Moreleta Park Plumbers & Electricians | B39: Trades & Home Services | C39: Gauteng | D39: Pretoria East | F39: 069 595 3715 | I39: No | J39: Google Maps | K39: New Lead | L39: 2026-04-04 | N39: 4.7 stars | 14 reviews | Monday: Open 24 hours | Tuesday: Open 24 hours | Wednesday: Open 24 hours | https://maps.google.com/?cid=3588421573338864152&g_mp=Cidnb29nbGUubWFwcy5wbGFjZXMudjEuUGxhY2VzLlNlYXJjaFRleHQQAhgEIAA | O39: 5 stars | P39: 1 reviews | Q39: Monday: Closed | R39: Tuesday: 8:00 AM – 5:00 PM | S39: Wednesday: 8:00 AM – 5:00 PM | T39: https://maps.google.com/?cid=6278432878887015311&g_mp=Cidnb29nbGUubWFwcy5wbGFjZXMudjEuUGxhY2VzLlNlYXJjaFRleHQQAhgEIAA
A40: CR Plumbers & Electricians-Garsfontein | B40: Trades & Home Services | C40: Gauteng | D40: Pretoria East | F40: 084 684 5336 | I40: No | J40: Google Maps | K40: New Lead | L40: 2026-04-04 | N40: 4.6 stars | 44 reviews | Monday: Open 24 hours | Tuesday: Open 24 hours | Wednesday: Open 24 hours | https://maps.google.com/?cid=2899791334340290673&g_mp=Cidnb29nbGUubWFwcy5wbGFjZXMudjEuUGxhY2VzLlNlYXJjaFRleHQQAhgEIAA | O40: 5 stars | P40: 37 reviews | Q40: Monday: 8:00 AM – 4:30 PM | R40: Tuesday: 8:00 AM – 4:30 PM | S40: Wednesday: 8:00 AM – 4:30 PM | T40: https://maps.google.com/?cid=7333345662632445409&g_mp=Cidnb29nbGUubWFwcy5wbGFjZXMudjEuUGxhY2VzLlNlYXJjaFRleHQQAhgEIAA
A41: LJs Lash&Beauty Lounge | B41: Beauty & Wellness | C41: Western Cape | D41: Durbanville | F41: 060 675 2114 | I41: No | J41: Google Maps | K41: New Lead | L41: 2026-04-04 | N41: 4.7 stars | 11 reviews | Monday: 9:00 AM – 5:00 PM | Tuesday: 9:00 AM – 7:00 PM | Wednesday: 9:00 AM – 5:00 PM | https://maps.google.com/?cid=9576612907672604464&g_mp=Cidnb29nbGUubWFwcy5wbGFjZXMudjEuUGxhY2VzLlNlYXJjaFRleHQQAhgEIAA | O41: 4.6 stars | P41: 14 reviews | Q41: Monday: 8:00 AM – 5:00 PM | R41: Tuesday: 8:00 AM – 5:00 PM | S41: Wednesday: 8:00 AM – 5:00 PM | T41: https://maps.google.com/?cid=2808044374855743598&g_mp=Cidnb29nbGUubWFwcy5wbGFjZXMudjEuUGxhY2VzLlNlYXJjaFRleHQQAhgEIAA
A42: Aesthetics By Bronwen | B42: Beauty & Wellness | C42: Western Cape | D42: Durbanville | I42: No | J42: Google Maps | K42: New Lead | L42: 2026-04-04 | N42: 5 stars | 10 reviews | Monday: 9:30 AM – 6:00 PM | Tuesday: Closed | Wednesday: 9:30 AM – 5:00 PM | https://maps.google.com/?cid=17404010385463475815&g_mp=Cidnb29nbGUubWFwcy5wbGFjZXMudjEuUGxhY2VzLlNlYXJjaFRleHQQAhgEIAA | O42: Monday: 8:00 AM – 6:00 PM | P42: Tuesday: 8:00 AM – 6:00 PM | Q42: Wednesday: 8:00 AM – 6:00 PM | R42: https://maps.google.com/?cid=14897248119382333190&g_mp=Cidnb29nbGUubWFwcy5wbGFjZXMudjEuUGxhY2VzLlNlYXJjaFRleHQQAhgEIAA
...

Sheet Dashboard
A1: Pipeline Dashboard
A2: Auto-calculated from the Lead Tracker sheet. Just keep your tracker updated.
A4: Total Leads | B4: Contacted | C4: Interested | D4: Won (Paid) | E4: Lost | F4: Conversion Rate
A5: =COUNTA('Lead Tracker'!B5:B197) | B5: =COUNTIF('Lead Tracker'!L5:L197,"Contacted")+COUNTIF('Lead Tracker'!L5:L197,"Interested")+COUNTIF('Lead Tracker'!L5:L197,"Demo Sent")+COUNTIF('Lead Tracker'!L5:L197,"Negotiating")+COUNTIF('Lead Tracker'!L5:L197,"Won - Paid")+COUNTIF('Lead Tracker'!L5:L197,"Lost") | C5: =COUNTIF('Lead Tracker'!L5:L197,"Interested")+COUNTIF('Lead Tracker'!L5:L197,"Demo Sent")+COUNTIF('Lead Tracker'!L5:L197,"Negotiating")+COUNTIF('Lead Tracker'!L5:L197,"Won - Paid") | D5: =COUNTIF('Lead Tracker'!L5:L197,"Won - Paid") | E5: =COUNTIF('Lead Tracker'!L5:L197,"Lost") | F5: =IF(B5=0,"—",D5/B5)
A7: Leads by Industry | E7: Leads by Source
A8: Industry | B8: Count | C8: Won | E8: Source | F8: Count | G8: Won
A9: Trades & Home Services | B9: =COUNTIF('Lead Tracker'!C5:C197,"Trades & Home Services") | C9: =COUNTIFS('Lead Tracker'!C5:C197,"Trades & Home Services",'Lead Tracker'!L5:L197,"Won - Paid") | E9: Google Maps | F9: =COUNTIF('Lead Tracker'!K5:K197,"Google Maps") | G9: =COUNTIFS('Lead Tracker'!K5:K197,"Google Maps",'Lead Tracker'!L5:L197,"Won - Paid")
A10: Beauty & Wellness | B10: =COUNTIF('Lead Tracker'!C5:C197,"Beauty & Wellness") | C10: =COUNTIFS('Lead Tracker'!C5:C197,"Beauty & Wellness",'Lead Tracker'!L5:L197,"Won - Paid") | E10: Facebook | F10: =COUNTIF('Lead Tracker'!K5:K197,"Facebook") | G10: =COUNTIFS('Lead Tracker'!K5:K197,"Facebook",'Lead Tracker'!L5:L197,"Won - Paid")
A11: Food & Hospitality | B11: =COUNTIF('Lead Tracker'!C5:C197,"Food & Hospitality") | C11: =COUNTIFS('Lead Tracker'!C5:C197,"Food & Hospitality",'Lead Tracker'!L5:L197,"Won - Paid") | E11: Instagram | F11: =COUNTIF('Lead Tracker'!K5:K197,"Instagram") | G11: =COUNTIFS('Lead Tracker'!K5:K197,"Instagram",'Lead Tracker'!L5:L197,"Won - Paid")
A12: Professional Services | B12: =COUNTIF('Lead Tracker'!C5:C197,"Professional Services") | C12: =COUNTIFS('Lead Tracker'!C5:C197,"Professional Services",'Lead Tracker'!L5:L197,"Won - Paid") | E12: Gumtree | F12: =COUNTIF('Lead Tracker'!K5:K197,"Gumtree") | G12: =COUNTIFS('Lead Tracker'!K5:K197,"Gumtree",'Lead Tracker'!L5:L197,"Won - Paid")
A13: Other | B13: =COUNTIF('Lead Tracker'!C5:C197,"Other") | C13: =COUNTIFS('Lead Tracker'!C5:C197,"Other",'Lead Tracker'!L5:L197,"Won - Paid") | E13: WhatsApp Group | F13: =COUNTIF('Lead Tracker'!K5:K197,"WhatsApp Group") | G13: =COUNTIFS('Lead Tracker'!K5:K197,"WhatsApp Group",'Lead Tracker'!L5:L197,"Won - Paid")
E14: Word of Mouth | F14: =COUNTIF('Lead Tracker'!K5:K197,"Word of Mouth") | G14: =COUNTIFS('Lead Tracker'!K5:K197,"Word of Mouth",'Lead Tracker'!L5:L197,"Won - Paid")
E15: Other | F15: =COUNTIF('Lead Tracker'!K5:K197,"Other") | G15: =COUNTIFS('Lead Tracker'!K5:K197,"Other",'Lead Tracker'!L5:L197,"Won - Paid")
A17: Revenue Projection
A18: Metric | B18: Value
A19: Build fee per client (R) | B19: 2000
A20: Monthly hosting fee (R) | B20: 250
A21: Clients won | B21: =D5
A22: Once-off revenue (R) | B22: =B19*B21
A23: Monthly recurring revenue (R) | B23: =B20*B21
A24: Projected annual recurring (R) | B24: =B23*12
A25: Year 1 total revenue (R) | B25: =B22+B24

Sheet Search Schedule
A1: Weekly Search Rotation
A2: Follow this schedule daily. 30 minutes a day builds a serious pipeline.
A4: Day | B4: Channel | C4: Industry Focus | D4: Areas to Search | E4: Target Leads
A5: Monday | B5: Google Maps | C5: Trades & Home Services | D5: Pick 3 suburbs in Gauteng | E5: 6-8
A6: Tuesday | B6: Facebook Pages | C6: Beauty & Wellness | D6: Pick 2 cities in Western Cape + KZN | E6: 4-6
A7: Wednesday | B7: Google Maps | C7: Food & Hospitality | D7: Pick 3 suburbs in KZN / Eastern Cape | E7: 6-8
A8: Thursday | B8: Instagram + Gumtree | C8: Professional Services | D8: Nationwide — use hashtags + categories | E8: 5-7
A9: Friday | B9: Directories (rotate) | C9: All — review tracker | D9: Yellow Pages / Snupit / Yoco | E9: 3-5
A10: Saturday | B10: Walk-by + word of mouth | C10: Any opportunity | D10: Your local area + community groups | E10: 2-4
A11: Sunday | B11: Rest / follow-ups | C11: — | D11: Review tracker, plan next week | E11: —
